Workbook

Sheet Assumptions
A1: Key Assumptions
A3: ข้อมูลประชากรและ Coverage Gap
A4: รายการ | B4: ค่า | C4: หน่วย | D4: Source
A5: ผู้สูงอายุทั้งหมด (ปี 2567) | B5: 13940000 | C5: คน | D5: NSO Survey 2567
A6: ผู้สูงอายุภาวะพึ่งพิง (ติดบ้าน+ติดเตียง) | B6: 686000 | C6: คน | D6: ERIA LTC Thailand Report
A7: เข้าถึงระบบ LTC จริง | B7: 300000 | C7: คน | D7: Pitch Deck / ERIA
A8: ตกหล่นจากระบบ | B8: 387000 | C8: คน | D8: 686,000 - 300,000 = 56%
A9: ถูกคัดกรองแล้ว (% ของผู้สูงอายุ) | B9: 0.55 | C9: % | D9: LTC_book.pdf บทที่ 5 หน้า 158
A10: ผู้สูงอายุที่ไม่เคยถูกคัดกรอง | B10: 6270000 | C10: คน | D10: 45% × 13.94M
A11: Coverage ในเขตเทศบาล | B11: 0.609 | C11: % | D11: LTC_book.pdf ตาราง 25 หน้า 174
A12: Coverage นอกเขตเทศบาล | B12: 0.8199 | C12: % | D12: LTC_book.pdf ตาราง 25 หน้า 174
A14: งบประมาณและต้นทุน LTC
A15: รายการ | B15: ค่า | C15: หน่วย | D15: Source
A16: งบ LTC capitation | B16: 6000 | C16: THB/คน/ปี | D16: สปสช. ปี 2568-2569
A17: ต้นทุนจริง (Option 1 ขั้นต่ำ) | B17: 24732 | C17: THB/คน/ปี | D17: LTC_book.pdf ตาราง 21 หน้า 161
A18: ต้นทุนจริง (Option 2 แนะนำ) | B18: 32680 | C18: THB/คน/ปี | D18: LTC_book.pdf ตาราง 21 หน้า 161
A19: ต้นทุนจริง (Option 3 เต็มรูปแบบ) | B19: 44677 | C19: THB/คน/ปี | D19: LTC_book.pdf ตาราง 21 หน้า 161
A20: งบ LTC ครอบคลุมต้นทุนจริง (%) | B20: 0.24 | C20: % | D20: 6,000 / 24,732 = 24%
A22: ค่าผ้าอ้อมและวัสดุ
A23: รายการ | B23: ค่า | C23: หน่วย | D23: Source
A24: ราคากลางรัฐบาล (ผ้าอ้อม) | B24: 9.5 | C24: THB/ชิ้น | D24: สปสช. ประกาศราคากลาง
A25: ราคาตลาดจริง (ผ้าอ้อม) | B25: 15.27 | C25: THB/ชิ้น | D25: LTC_book.pdf ตาราง 13 หน้า 146
A26: ราคากลาง (แผ่นรองซับ) | B26: 4.7 | C26: THB/ชิ้น | D26: สปสช.
A27: ราคาตลาด (แผ่นรองซับ) | B27: 8.17 | C27: THB/ชิ้น | D27: LTC_book.pdf
A28: ผ้าอ้อมใช้/สัปดาห์ (ติดเตียง) | B28: 20.1 | C28: ชิ้น | D28: LTC_book.pdf หน้า 146
A29: ค่าผ้าอ้อม/คน/เดือน | B29: 1320 | C29: THB | D29: 20.1 × 4.33 × 15.27
A30: ค่าแผ่นรองซับ/คน/เดือน | B30: 468 | C30: THB | D30: 13.3 × 4.33 × 8.17
A31: รวมค่าวัสดุสิ้นเปลือง/คน/เดือน | B31: 3242 | C31: THB | D31: LTC_book.pdf
A32: ค่าดูแล LTC ทั้งหมด/คน/เดือน (ติดเตียง) | B32: 19129 | C32: THB | D32: LTC_book.pdf
A34: บุคลากร
A35: รายการ | B35: ค่า | C35: หน่วย | D35: Source
A36: CM ทั้งระบบ (ปี 2567) | B36: 20220 | C36: คน | D36: LTC_book.pdf ตาราง 11 หน้า 137
A37: CG ทั้งระบบ (ปี 2567) | B37: 106650 | C37: คน | D37: LTC_book.pdf ตาราง 11
A38: CG:CM ratio | B38: 5.3 | C38: ต่อ 1 | D38: LTC_book.pdf
A39: CM ค่าตอบแทน/care plan | B39: 100 | C39: THB/ราย | D39: LTC_book.pdf หน้า 135
A40: CG ค่าตอบแทนจริง/เดือน | B40: 1620 | C40: THB | D40: Khongboon et al. 2023
A41: CG เป้าหมาย | B41: 50000 | C41: คน | D41: แผนยุทธศาสตร์
A42: CG ขาดแคลน (ปี 2569) | B42: 117075 | C42: คน | D42: LTC_book.pdf หน้า 139
A44: โครงสร้างพื้นฐานที่มีอยู่
A45: รายการ | B45: ค่า | C45: หน่วย | D45: Source
...

Sheet CAPEX
A1: CAPEX
A2: ค่าพัฒนาระบบ LaPooPoo Platform ประมาณการสำหรับ Phase 1 Pilot
A4: รายการ | B4: จำนวนเงิน (THB) | C4: หมายเหตุ
A5: Platform Development
A6: Frontend Dashboard (Next.js / React) | B6: 300000 | C6: UI, responsive, 11 tabs
A7: Backend API & HOSxP Integration | B7: 500000 | C7: HL7 FHIR adapter, ICD-10 trigger
A8: AI Care Plan Engine (LLM + RAG) | B8: 200000 | C8: Groq qwen3-32b, prompt engineering
A9: Line OA Agent Development | B9: 150000 | C9: ADL assessment chatbot, QR tracking
A10: Command Center Dashboard (สปสช.) | B10: 250000 | C10: Realtime SLA, coverage maps
A11: Subtotal Platform Development | B11: =SUM(B6:B10)
A12: Infrastructure Setup
A13: Cloud Server & CDN (Vercel/AWS) | B13: 50000 | C13: Initial provisioning
A14: Security & Compliance Audit | B14: 100000 | C14: PDPA, data encryption, pen-test
A15: Database Setup (PostgreSQL) | B15: 30000 | C15: Schema, migration, backup config
A16: Subtotal Infrastructure | B16: =SUM(B13:B15)
A17: Training & Onboarding
A18: อสม. Training Materials & Workshop | B18: 80000 | C18: Line OA tutorial, video guides
A19: CM Training Program | B19: 50000 | C19: AI-assisted workflow, dashboard
A20: Documentation & User Guides | B20: 40000 | C20: Thai-language manuals
A21: Subtotal Training | B21: =SUM(B18:B20)
A23: TOTAL CAPEX | B23: =B11+B16+B21

Sheet OPEX
A1: OPEX
A2: แบ่งตาม 3 Phases (Monthly + Annual)
A4: รายการ | B4: Phase 1 /เดือน | C4: Phase 1 /ปี | D4: Phase 2 /เดือน | E4: Phase 2 /ปี | F4: Phase 3 /เดือน | G4: Phase 3 /ปี | H4: หมายเหตุ
A5: Cloud Hosting (Vercel/AWS) | B5: 5000 | C5: =B5*12 | D5: 15000 | E5: =D5*12 | F5: 40000 | G5: =F5*12 | H5: Scale with traffic
A6: AI API Costs (Groq LLM) | B6: 2000 | C6: =B6*12 | D6: 8000 | E6: =D6*12 | F6: 25000 | G6: =F6*12 | H6: ~4 THB/care plan
A7: Line OA Messaging | B7: 1500 | C7: =B7*12 | D7: 5000 | E7: =D7*12 | F7: 15000 | G7: =F7*12 | H7: 0.20 THB/msg
A8: Maintenance & Support | B8: 20000 | C8: =B8*12 | D8: 50000 | E8: =D8*12 | F8: 120000 | G8: =F8*12 | H8: Dev team
A9: อสม. Incentive (top-up) | B9: 0 | C9: =B9*12 | D9: 10000 | E9: =D9*12 | F9: 75000 | G9: =F9*12 | H9: 1,000 THB/อสม./mo
A10: Data Storage & Backup | B10: 1000 | C10: =B10*12 | D10: 3000 | E10: =D10*12 | F10: 8000 | G10: =F10*12 | H10: PostgreSQL + S3
A11: Security Monitoring | B11: 2000 | C11: =B11*12 | D11: 5000 | E11: =D11*12 | F11: 10000 | G11: =F11*12 | H11: PDPA compliance
A12: Miscellaneous / Contingency | B12: 3000 | C12: =B12*12 | D12: 8000 | E12: =D12*12 | F12: 20000 | G12: =F12*12 | H12: 10% buffer
A13: TOTAL OPEX | B13: =SUM(B5:B12) | C13: =SUM(C5:C12) | D13: =SUM(D5:D12) | E13: =SUM(E5:E12) | F13: =SUM(F5:F12) | G13: =SUM(G5:G12)
A15: TOTAL COST (CAPEX + OPEX) | C15: =CAPEX!B23+C13 | E15: =CAPEX!B23+E13 | G15: =CAPEX!B23+G13

Sheet Cost per Patient
A1: Cost per Patient
A2: ผลกระทบต่อค่าใช้จ่ายต่อผู้ป่วย 1 รายเมื่อใช้ระบบ LaPooPoo
A4: รายการ | B4: As-Is (ปัจจุบัน) | C4: To-Be (LaPooPoo) | D4: Savings | E4: หมายเหตุ
A5: เวลาเข้าถึงสิทธิ์ผ้าอ้อม (วัน) | B5: 45 | C5: 14 | D5: =B5-C5 | E5: Pitch Deck target
A6: จำนวน Care Plan / CM / ปี | B6: 50 | C6: 150 | D6: =C6-B6 | E6: AI-assisted 3x capacity
A7: เวลาประเมิน ADL (นาที/ราย) | B7: 45 | C7: 10 | D7: =B7-C7 | E7: Line Agent auto-assess
A8: ค่าดำเนินการ Care Plan / ราย (THB) | B8: 2500 | C8: 800 | D8: =B8-C8 | E8: ลดเอกสาร 80%
A9: ค่าผ้าอ้อม/คน/ปี ภาระครอบครัว (THB) | B9: 15840 | C9: 5700 | D9: =B9-C9 | E9: ซื้อเองลดลงเมื่อเข้าถึงสิทธิ์
A10: ค่า Readmission ที่ป้องกันได้/ราย/ปี | B10: 15000 | C10: 3000 | D10: =B10-C10 | E10: 20% prevention rate × 75K
A11: ค่ารักษา Pressure Wound/ราย/ปี | B11: 6750 | C11: 2025 | D11: =B11-C11 | E11: ลด 70% ด้วย early diaper access
A12: Platform cost / ผู้ป่วย / ปี (at scale) | B12: 0 | C12: 250 | D12: =B12-C12 | E12: OPEX / จำนวนผู้ป่วย
A13: ต้นทุนรวม/ผู้ป่วย/ปี (ระบบ+ครอบครัว) | B13: 40090 | C13: 11775 | D13: =B13-C13 | E13: Sum above
A14: TOTAL SAVINGS / ผู้ป่วย / ปี | D14: =SUM(D5:D13)

Sheet KPI Forecast
A1: KPI Forecast — 3-Year Quarterly Projection
A2: Phase 1 (Y1), Phase 2 (Y2), Phase 3 (Y3)
A4: KPI | B4: Unit | C4: Y1Q1 | D4: Y1Q2 | E4: Y1Q3 | F4: Y1Q4 | G4: Y2Q1 | H4: Y2Q2 | I4: Y2Q3 | J4: Y2Q4 | K4: Y3Q1 | L4: Y3Q2 | M4: Y3Q3 | N4: Y3Q4
C5: Phase 1 (พ.ค. 2569 - ก.พ. 2570) | G5: Phase 2 (ก.พ. 2570 - ก.พ. 2571) | K5: Phase 3 (ก.พ. 2571 - ก.พ. 2572)
A6: รพ. เชื่อมต่อ HOSxP (สะสม) | B6: แห่ง | C6: 2 | D6: 3 | E6: 3 | F6: 3 | G6: 5 | H6: 8 | I6: 12 | J6: 18 | K6: 25 | L6: 40 | M6: 60 | N6: 80
A7: ผู้ป่วยค้นพบใหม่ (ต่อไตรมาส) | B7: คน | C7: 50 | D7: 150 | E7: 400 | F7: 800 | G7: 1500 | H7: 2500 | I7: 4000 | J7: 6000 | K7: 8000 | L7: 10000 | M7: 12000 | N7: 15000
A8: ผู้ป่วยค้นพบสะสม | B8: คน | C8: 50 | D8: 200 | E8: 600 | F8: 1400 | G8: 2900 | H8: 5400 | I8: 9400 | J8: 15400 | K8: 23400 | L8: 33400 | M8: 45400 | N8: 60400
A9: Care Plan อนุมัติ (สะสม) | B9: ฉบับ | C9: 30 | D9: 150 | E9: 450 | F9: 1100 | G9: 2300 | H9: 4500 | I9: 8000 | J9: 13500 | K9: 21000 | L9: 30500 | M9: 42000 | N9: 56000
A10: เวลาเฉลี่ยเข้าถึงสิทธิ์ | B10: วัน | C10: 45 | D10: 38 | E10: 30 | F10: 25 | G10: 20 | H10: 18 | I10: 16 | J10: 15 | K10: 14 | L10: 14 | M10: 14 | N10: 14
A11: CM capacity (cases/CM/yr) | B11: ราย | C11: 50 | D11: 65 | E11: 80 | F11: 100 | G11: 120 | H11: 130 | I11: 140 | J11: 145 | K11: 150 | L11: 150 | M11: 150 | N11: 150
A12: อสม. ใช้ Line Agent | B12: คน | C12: 10 | D12: 30 | E12: 80 | F12: 150 | G12: 300 | H12: 500 | I12: 800 | J12: 1200 | K12: 1800 | L12: 2500 | M12: 3500 | N12: 5000
A13: Coverage Rate Increase | B13: % | C13: 0.001 | D13: 0.003 | E13: 0.008 | F13: 0.02 | G13: 0.04 | H13: 0.07 | I13: 0.12 | J13: 0.2 | K13: 0.3 | L13: 0.42 | M13: 0.58 | N13: 0.78
A14: OPEX / ไตรมาส | B14: THB | C14: 103500 | D14: 103500 | E14: 103500 | F14: 103500 | G14: 312000 | H14: 312000 | I14: 312000 | J14: 312000 | K14: 939000 | L14: 939000 | M14: 939000 | N14: 939000
A15: Cost Savings / ไตรมาส | B15: THB | C15: 0 | D15: 750000 | E15: 3000000 | F15: 8000000 | G15: 18750000 | H15: 37500000 | I15: 62500000 | J15: 95000000 | K15: 130000000 | L15: 170000000 | M15: 210000000 | N15: 260000000
A16: ROI สะสม (Savings - Cost) | B16: THB | C16: =(C15)-(C14)-CAPEX!B23 | D16: =(C15+D15)-(C14+D14)-CAPEX!B23 | E16: =(C15+D15+E15)-(C14+D14+E14)-CAPEX!B23 | F16: =(C15+D15+E15+F15)-(C14+D14+E14+F14)-CAPEX!B23 | G16: =(C15+D15+E15+F15+G15)-(C14+D14+E14+F14+G14)-CAPEX!B23 | H16: =(C15+D15+E15+F15+G15+H15)-(C14+D14+E14+F14+G14+H14)-CAPEX!B23 | I16: =(C15+D15+E15+F15+G15+H15+I15)-(C14+D14+E14+F14+G14+H14+I14)-CAPEX!B23 | J16: =(C15+D15+E15+F15+G15+H15+I15+J15)-(C14+D14+E14+F14+G14+H14+I14+J14)-CAPEX!B23 | K16: =(C15+D15+E15+F15+G15+H15+I15+J15+K15)-(C14+D14+E14+F14+G14+H14+I14+J14+K14)-CAPEX!B23 | L16: =(C15+D15+E15+F15+G15+H15+I15+J15+K15+L15)-(C14+D14+E14+F14+G14+H14+I14+J14+K14+L14)-CAPEX!B23 | M16: =(C15+D15+E15+F15+G15+H15+I15+J15+K15+L15+M15)-(C14+D14+E14+F14+G14+H14+I14+J14+K14+L14+M14)-CAPEX!B23 | N16: =(C15+D15+E15+F15+G15+H15+I15+J15+K15+L15+M15+N15)-(C14+D14+E14+F14+G14+H14+I14+J14+K14+L14+M14+N14)-CAPEX!B23

Sheet Impact Summary
A1: Social Impact Summary — ผลลัพธ์ 3 ปี
A2: LaPooPoo Platform: เปลี่ยนสิทธิ์บนกระดาษให้เป็นสิทธิ์ที่เข้าถึงได้จริง
A4: 1. คนเข้าถึงสิทธิ์ — Rights Access
A5: ตัวชี้วัด | B5: ก่อนใช้ระบบ | C5: หลังใช้ระบบ (3 ปี) | D5: ความหมาย
A6: ผู้ป่วยค้นพบและเข้าถึงสิทธิ์ใหม่ | B6: 0 (รอ อสม. สำรวจ) | C6: 60,400 คน | D6: ค้นพบอัตโนมัติจาก ICD-10 trigger ใน รพ.
A7: Coverage Gap (ผู้สูงอายุตกหล่น) | B7: 56% (387,000 คน) | C7: Target < 20% | D7: ลดจำนวนคนตกหล่น ~250,000+ คน
A8: เวลาเข้าถึงสิทธิ์ผ้าอ้อม | B8: 45 วัน (บางราย 3+ เดือน) | C8: 14 วัน | D8: ลด 69% — ได้ผ้าอ้อมเร็วขึ้น 1 เดือน
A9: Care Plan อนุมัติสะสม | B9: คิวรอ 1-3 เดือน | C9: 56,000 ฉบับ (≤7 วัน) | D9: AI ร่าง → CM อนุมัติ ไม่ต้องเริ่มจากศูนย์
A11: 2. ภาระครอบครัวลดลง — Family Burden Reduction
A12: ตัวชี้วัด | B12: ก่อนใช้ระบบ | C12: หลังใช้ระบบ | D12: ความหมาย
A13: ค่าผ้าอ้อมที่ครอบครัวต้องจ่ายเอง/ปี | B13: 15,840 บาท/คน/ปี | C13: 5,700 บาท/คน/ปี | D13: ประหยัด 10,140 บาท/ครอบครัว/ปี
A14: รวมภาระที่ลดได้ (60,400 ครอบครัว × 3 ปี) | B14: - | C14: ~612 ล้านบาท | D14: เงินที่ครอบครัวไม่ต้องควักจ่ายเอง
A15: Pressure Wound ที่ป้องกันได้ | B15: - | C15: ~8,500 case | D15: ลดความเจ็บปวด ลดค่ารักษาเพิ่ม
A16: Readmission ที่ป้องกันได้ | B16: - | C16: ~12,000 ครั้ง | D16: ผู้ป่วยไม่ต้องกลับ รพ. ซ้ำ
A18: 3. บุคลากรด่านหน้าทำงานได้มากขึ้น — Workforce Capacity
A19: ตัวชี้วัด | B19: ก่อนใช้ระบบ | C19: หลังใช้ระบบ | D19: ความหมาย
A20: CM Capacity (ราย/CM/ปี) | B20: 50 ราย | C20: 150 ราย | D20: เพิ่ม 3 เท่า โดยไม่ต้องจ้างเพิ่ม
A21: เทียบเท่าการจ้าง CM เพิ่ม | B21: - | C21: ~800 คน | D21: ประหยัดค่าจ้าง แต่ดูแลได้เท่ากัน
A22: เวลาประเมิน ADL / ราย | B22: 45 นาที (ลงพื้นที่) | C22: 10 นาที (Line Agent) | D22: ลด 78% — ญาติตอบเอง CM ตรวจสอบ
A23: ภาระเอกสาร/Care Plan | B23: 4 ชุดเอกสาร × 3 ระบบ | C23: 0 กระดาษ (Digital) | D23: ลด 100% — Single Source of Truth
A24: อสม. ใช้ Line Agent | B24: 0 | C24: 5,000 คน | D24: เครื่องมือใหม่ให้ อสม. ทำงานเชิงรุก
A26: ต้นทุนแพลตฟอร์ม (ข้อมูลสนับสนุน)
A27: CAPEX (ลงทุนครั้งเดียว) | B27: 1,750,000 บาท | D27: Platform + Infra + Training
A28: OPEX 3 ปี | B28: 5,418,000 บาท | D28: Cloud + AI + Maintenance + Support
A29: Total Platform Cost 3 ปี | B29: 7,168,000 บาท | D29: เฉลี่ย ~119 บาท/ผู้ป่วย/ปี
A31: → ลงทุน 119 บาท/คน/ปี เพื่อให้ผู้ป่วย 60,400 คน เข้าถึงสิทธิ์ผ้าอ้อมที่ควรได้รับ
A32: → ลดภาระครอบครัวเฉลี่ย 10,140 บาท/ปี ด้วยการเข้าถึงสิทธิ์ที่มีอยู่แล้วแต่เข้าไม่ถึง
A33: → CM 1 คน ดูแลได้เพิ่มขึ้น 3 เท่า — เทียบเท่าจ้างเพิ่ม 800 คน โดยไม่เพิ่มงบบุคลากร
